<?xml version="1.0"?>
<robot xmlns:xacro="http://www.ros.org/wiki/xacro">

    <!-- Base Link -->
    <link name="base_link">
    </link>

    <!-- BASE_FOOTPRINT LINK -->
    <joint name="base_footprint_joint" type="fixed">
        <parent link="base_link"/>
        <child link="base_footprint"/>
        <origin xyz="0 0 0" rpy="0 0 0"/>
    </joint>

    <link name="base_footprint">
    </link>

    <!-- Chassis Link -->
    <joint name="chassis_joint" type="fixed">
        <parent link="base_link"/>
        <child link="chassis"/>
        <origin xyz="-0.0365 0 0"/>
    </joint>

    <!-- Chassis 137.6mm² -->
    <link name="chassis">
        <visual>
            <origin xyz="0.069 0 0.0865" rpy="0 0 0"/>
            <geometry>
                <box size="0.138 0.138 0.173"/>
            </geometry>
            <material name="white"/>
        </visual>
        <collision>
            <origin xyz="0.069 0 0.0865" rpy="0 0 0"/>
            <geometry>
                <box size="0.138 0.138 0.173"/>
            </geometry>
            <material name="white"/>
        </collision>
        <xacro:inertial_box mass="1.6" x="0.138" y="0.138" z="0.173">
            <origin xyz="0.069 0 0.0865" rpy="0 0 0"/>
        </xacro:inertial_box>
    </link>
    <gazebo reference="chassis">
        <material>Gazebo/Orange</material>
    </gazebo>

    <!-- LEFT WHEEL 66mm diameter, 18mm wide-->
    <joint name="left_wheel_joint" type="continuous">
        <parent link="base_link"/>
        <child link="left_wheel"/>
        <origin xyz="0 0.08 0.023" rpy="-${pi/2} 0 0"/>
        <axis xyz="0 0 1"/>
    </joint>

    <link name="left_wheel">
        <visual>
            <geometry>
                <cylinder length="0.018" radius="0.033" />
            </geometry>
            <material name="blue"/>
        </visual>
        <collision>
            <geometry>
                <cylinder length="0.018" radius="0.033" />
            </geometry>
            <material name="blue"/>
        </collision>
        <xacro:inertial_cylinder mass="0.1" length="0.018" radius="0.033">
            <origin xyz="0 0 0" rpy="0 0 0"/>
        </xacro:inertial_cylinder>
    </link>
    <gazebo reference="left_wheel">
        <material>Gazebo/Blue</material>
    </gazebo>

    <!-- RIGHT WHEEL -->
    <joint name="right_wheel_joint" type="continuous">
        <parent link="base_link"/>
        <child link="right_wheel"/>
        <origin xyz="0 -0.08 0.023" rpy="${pi/2} 0 0"/>
        <axis xyz="0 0 -1"/>
    </joint>

    <link name="right_wheel">
        <visual>
            <geometry>
                <cylinder length="0.018" radius="0.033" />
            </geometry>
            <material name="blue"/>
        </visual>
        <collision>
            <geometry>
                <cylinder length="0.018" radius="0.033" />
            </geometry>
            <material name="blue"/>
        </collision>
        <xacro:inertial_cylinder mass="0.1" length="0.018" radius="0.033">
            <origin xyz="0 0 0" rpy="0 0 0"/>
        </xacro:inertial_cylinder>
    </link>
    <gazebo reference="right_wheel">
        <material>Gazebo/Blue</material>
    </gazebo>

    <!-- CASTER WHEEL 10mm diameter-->
    <joint name="caster_wheel_joint" type="fixed">
        <parent link="chassis"/>
        <child link="caster_wheel"/>
        <origin xyz="0.12 0 -0.005" rpy="0 0 0"/>
    </joint>

    <link name="caster_wheel">
        <visual>
            <geometry>
                <sphere radius="0.005" />
            </geometry>
            <material name="black"/>
        </visual>
        <collision>
            <geometry>
                <sphere radius="0.005" />
            </geometry>
            <material name="black"/>
        </collision>
    </link>
    <gazebo reference="caster_wheel">
        <material>Gazebo/Black</material>
        <mu1 value="0.001"/>
        <mu2 value="0.001"/>
    </gazebo>

</robot>